Workbook
Name ExternalData_1: 'Periodic Reflection'!$KJ$418:$KK$420

Sheet READ ME
A1: Instructions
A2: Trading Log Template (Action-Based) How to use: 1) Record EVERY action as a new row on the 'Trading Log' sheet: • Open: starting a new position • Adjust: changing size (Quantity is the change; positive to add, negative to reduce) • Close: closing part or all of a position (Quantity = number of units closed) • No Action: use once per reporting period if you made no changes; explain why 2) Keep 'Position After Trade' updated so we can see the running position size. 3) Provide a brief reason in the last column (or for 'No Action', a short rationale for holding). 4) Add longer commentary in the 'Explanations' sheet at the end of each reporting period. Notes: • 'Gross Trade Value' and 'Net Trade Value' can be formula-based (Qty*Price minus fees) or entered manually. • Use the drop-downs for 'Action', 'Type', and 'Trade Currency'. • We are NOT assessing portfolio performance here; the goal is to track decisions and rationale. • Delete the 'Example (delete)' sheet before submission.

Sheet Cover
A1: #VALUE!
B5: Trading Log | K5: =1+1+1+1 -> 4
J6: -
G11: Team 5 Lon 2
B12: The Investment Challenge - CHL-0200 | H12: Abdul Rafay Malik
B13: Prof. Daniela Neiderer | H13: Aliah Muhammad Asharaf
H14: Azriel Fernandes
B15: Date: | C15: 46111 | H15: Devarya Shah
H16: Kartavya Jharwal
H17: Nandini Prakash Rangani
H18: Pedro Junqueira
H19: Sayhan Mushrif

Sheet Trading Log
A1: Date (YYYY-MM-DD) | B1: Action (Open / Close / Adjust / No Action) | C1: Ticker | D1: Asset Name | E1: Type (Stock, ETF, Bond, FX, etc.) | F1: Quantity (positive number) | G1: Price per Unit | H1: Trade Currency | I1: Gross Trade Value (=Qty*Price) | J1: Fees / Commission | K1: Net Trade Value | L1: Position After Trade (units) | M1: Brief Reason (or reason for no change)
A3: 46084 | B3: No Action | C3: SPY | D3: SPDR S&P 500 ETF Trust | E3: ETF | F3: 295 | G3: 684.89 | H3: USD | I3: =TradingLogTable3[[#This Row],[Quantity (positive number)]]*TradingLogTable3[[#This Row],[Price per Unit]] -> 202042.55 | J3: 10 | K3: =I3+J3 -> 202052.55 | L3: 295 | M3: Core benchmark exposure. Portfolio outperforming S&P this period. Thesis unchanged; no stop-loss on index. Hold.
A4: 46084 | B4: No Action | C4: XLP | D4: Consumer Staples Select Sector SPDR | E4: ETF | F4: 875 | G4: 89.52 | H4: USD | I4: 78330 | J4: 10 | K4: 78340 | L4: 875 | M4: Consumer staples ETF. Minor unrealized loss within normal range. Defensive allocation working as intended. Hold.
A5: 46084 | B5: No Action | C5: JNJ | D5: Johnson & Johnson | E5: Stock | F5: 260 | G5: 244.64 | H5: USD | I5: 63606.4 | J5: 10 | K5: 63616.4 | L5: 260 | M5: Healthcare defensive. Stable earnings and dividend profile unchanged. Hold.
A6: 46084 | B6: No Action | C6: PG | D6: Procter & Gamble Co. | E6: Stock | F6: 235 | G6: 162.45 | H6: USD | I6: 38175.75 | J6: 10 | K6: 38185.75 | L6: 235 | M6: FMCG defensive. Strong global brands and resilient demand. Hold.
A7: 46084 | B7: No Action | C7: WMT | D7: Walmart Inc. | E7: Stock | F7: 570 | G7: 132.95 | H7: USD | I7: 75781.5 | J7: 10 | K7: 75791.5 | L7: 570 | M7: Down about 5%. Retail under pressure, but defensive thesis intact. Stop-loss placed at $118. Monitor.
A8: 46084 | B8: No Action | C8: XLU | D8: Utilities Select Sector SPDR | E8: ETF | F8: 800 | G8: 45.45 | H8: USD | I8: 36360 | J8: 10 | K8: 36370 | L8: 800 | M8: Utilities ETF. Low‑beta defensive working during volatility. Hold.
A9: 46084 | B9: No Action | C9: TSM | D9: Taiwan Semiconductor Manufacturing – ADR | E9: Stock | F9: 230 | G9: 363.94 | H9: USD | I9: 83706.2 | J9: 10 | K9: 83716.2 | L9: 230 | M9: AI foundry thesis intact and strengthening. Guidance unchanged. Hold.
A10: 46084 | B10: Adjust | C10: MU | D10: Micron Technology Inc. | E10: Stock | F10: 95 | G10: 381.14 | H10: USD | I10: -36208.3 | J10: 10 | K10: -36198.3 | L10: 15 | M10: Trailing stop-loss on MU triggered; trimmed 95 shares after strong run, kept 15‑share residual for AI memory thesis.
A11: 46084 | B11: No Action | C11: PLTR | D11: Palantir Technologies Inc. | E11: Stock | F11: 388 | G11: 131.48 | H11: USD | I11: 51014.24 | J11: 10 | K11: 51024.24 | L11: 388 | M11: AI defense software thesis intact. Volatility within acceptable range. Hold.
A12: 46084 | B12: No Action | C12: JPM | D12: JPMorgan Chase & Co. | E12: Stock | F12: 150 | G12: 306.82 | H12: USD | I12: 46023 | J12: 10 | K12: 46033 | L12: 150 | M12: Slight drawdown on rate repricing. Banking fundamentals unchanged. Hold (before later exit).
A13: 46084 | B13: No Action | C13: AMZN | D13: Amazon.com Inc. | E13: Stock | F13: 250 | G13: 200.87 | H13: USD | I13: 50217.5 | J13: 10 | K13: 50227.5 | L13: 250 | M13: AWS cloud and e‑commerce thesis intact; AI workloads support demand. Hold.
A14: 46084 | B14: No Action | C14: GOOGL | D14: Alphabet Inc – Class A | E14: Stock | F14: 130 | G14: 302.22 | H14: USD | I14: 39288.6 | J14: 10 | K14: 39298.6 | L14: 130 | M14: Big tech AI infrastructure thesis intact. Gemini and search dominance support. Trailing stop at 7%. Hold.
A15: 46084 | B15: No Action | C15: GE | D15: GE Aerospace | E15: Stock | F15: 140 | G15: 329.44 | H15: USD | I15: 46121.6 | J15: 10 | K15: 46131.6 | L15: 140 | M15: Industrial/aerospace thesis intact. Up ~3%. Trailing stop at 5% in place prior to trigger. Hold at check‑in.
... A32: 46097 | B32: Open | C32: SIEGY | D32: Siemens AG – ADR | E32: Stock | F32: 150 | G32: 126.695 | H32: USD | I32: 19004.25 | J32: 10 | K32: 19014.25 | L32: 150 | M32: European industrial core with strong electrification/automation order book, adding non‑US energy‑transition exposure beyond XOM/XLE.
G33: ='Live Data'!Q33 -> 0 | I33: =TradingLogTable3[[#This Row],[Quantity (positive number)]]*TradingLogTable3[[#This Row],[Price per Unit]] -> 0 | K33: =I33+J33 -> 0
A34: 24/03/2026 | B34: No Action | C34: SPY | D34: SPDR S&P 500 ETF Trust | E34: ETF | F34: 295 | G34: 684.89 | H34: USD | I34: =F34*G34 -> 202042.55 | J34: 10 | K34: =I34+J34 -> 202052.55 | L34: 295 | M34: Core benchmark exposure; no rebalance as portfolio maintaint to outperrform without excess risk concentration
A35: 24/03/2026 | B35: No Action | C35: XLP | D35: Consumer Staples Select Sector SPDR | E35: ETF | F35: 440 | G35: 89.52 | H35: USD | I35: =F35*G35 -> 39388.8 | J35: 10 | K35: =I35+J35 -> 39398.8 | L35: 440 | M35: Defensive allocation maintained after prior reduction; it helps maintin stabillity in our portfolio against external macro volatility
A36: 24/03/2026 | B36: No Action | C36: JNJ | D36: Johnson & Johnson | E36: Stock | F36: 260 | G36: 244.64 | H36: USD | I36: =F36*G36 -> 63606.4 | J36: 10 | K36: =I36+J36 -> 63616.4 | L36: 260 | M36: Healthcare defensive with consistent earnign and dividend; there are no catalysts to justify realloction
A37: 24/03/2026 | B37: No Action | C37: PG | D37: Procter & Gamble Co. | E37: Stock | F37: 235 | G37: 162.45 | H37: USD | I37: =F37*G37 -> 38175.75 | J37: 10 | K37: =I37+J37 -> 38185.75 | L37: 235 | M37: Strong pricing power and has a lot of demadn; remains a low-volatiltiy consumer staple anchor
A38: 24/03/2026 | B38: No Action | C38: XLU | D38: Utilities Select Sector SPDR | E38: ETF | F38: 800 | G38: 45.45 | H38: USD | I38: =F38*G38 -> 36360 | J38: 10 | K38: =I38+J38 -> 36370 | L38: 800 | M38: The utilities ETF is held as a low-beta hedge against equity market drawdowns and rate uncertainity
A39: 24/03/2026 | B39: No Action | C39: TSM | D39: Taiwan Semiconductor Manufacturing – ADR | E39: Stock | F39: 230 | G39: 363.94 | H39: USD | I39: =F39*G39 -> 83706.2 | J39: 10 | K39: =I39+J39 -> 83716.2 | L39: 230 | M39: AI supply-chain leader; maintained demand from hyperscalers back the long-term growth thesis
A40: 24/03/2026 | B40: No Action | C40: MU | D40: Micron Technology Inc. | E40: Stock | F40: 15 | G40: 408.82 | H40: USD | I40: =F40*G40 -> 6132.3 | J40: 10 | K40: =I40+J40 -> 6142.3 | L40: 15 | M40: Small position reatained post-trim; keeps exposure to cyclical AI memory upside wothout adding risk
A41: 24/03/2026 | B41: No Action | C41: PLTR | D41: Palantir Technologies Inc. | E41: Stock | F41: 388 | G41: 131.48 | H41: USD | I41: =F41*G41 -> 51014.24 | J41: 10 | K41: =I41+J41 -> 51024.24 | L41: 388 | M41: AI and defense software remains strong; the volatility is currently within the acceptable tange and there are no adjustments needed
A42: 24/03/2026 | B42: No Action | C42: AMZN | D42: Amazon.com Inc. | E42: Stock | F42: 250 | G42: 200.87 | H42: USD | I42: =F42*G42 -> 50217.5 | J42: 10 | K42: =I42+J42 -> 50227.5 | L42: 250 | M42: AWS and AI-driven cloud growht maintains to support revenue exapnasion; long term thesis intact
A43: 24/03/2026 | B43: No Action | C43: IONQ | D43: IonQ Inc | E43: Stock | F43: 800 | G43: 33.6 | H43: USD | I43: =F43*G43 -> 26880 | J43: 10 | K43: =I43+J43 -> 26890 | L43: 800 | M43: High-risk specualtive position maintained through small allocation; long-term optionality outweighs short-term volatility
A44: 24/03/2026 | B44: No Action | C44: XLE | D44: Energy Select Sector SPDR | E44: ETF | F44: 60 | G44: 57.95 | H44: USD | I44: =F44*G44 -> 3477 | J44: 10 | K44: =I44+J44 -> 3487 | L44: 60 | M44: Retained due to tactical hedge against geopolitical risks and increased oil price envrionment
A45: 24/03/2026 | B45: No Action | C45: XOM | D45: Exxon Mobil Corp | E45: Stock | F45: 75 | G45: 159.75 | H45: USD | I45: =F45*G45 -> 11981.25 | J45: 10 | K45: =I45+J45 -> 11991.25 | L45: 75 | M45: Strong cash flow and oil price backs continued exposure as energy hedge
... A54: 24/03/2026 | B54: No Action | C54: SIEGY | D54: Siemens AG – ADR | E54: Stock | F54: 150 | G54: 126.7 | H54: USD | I54: =F54*G54 -> 19005 | J54: 10 | K54: =I54+J54 -> 19015 | L54: 150 | M54: European industrial exposure with upside from electrification trends.
A55: ----- | B55: ----- | C55: ----- | D55: ----- | E55: ----- | F55: EMEREGENCY | G55: TRIAGE | H55: MODE | I55: ----- | J55: ----- | K55: ----- | L55: ----- | M55: -----
A56: 46111 | B56: Close | C56: SPY | D56: SPDR S&P 500 ETF Trust | E56: ETF | F56: 295 | G56: 631.64 | H56: USD | I56: -186333.8 | J56: 10 | K56: -186323.8 | L56: 0 | M56: Emergency charter override: liquidating core index position as market selloff accelerates. Reallocating to inverse ETFs and safe havens.
A57: 46111 | B57: Adjust | C57: TSM | D57: Taiwan Semiconductor Manufacturing – ADR | E57: Stock | F57: 230 | G57: 315.12 | H57: USD | I57: 72477.6 | J57: 10 | K57: 72487.6 | L57: 460 | M57: Execution error: Misclick resulted in additional 230 shares purchased instead of sell. Corrective sell executed immediately after.
A58: 46111 | B58: Close | C58: TSM | D58: Taiwan Semiconductor Manufacturing – ADR | E58: Stock | F58: 460 | G58: 314.7 | H58: USD | I58: -144762 | J58: 10 | K58: -144752 | L58: 0 | M58: Corrective full close of TSM. Geopolitical panic and Nasdaq correction dragging semiconductors down regardless of fundamental guidance.
A59: 46111 | B59: Adjust | C59: TGT | D59: Target Corp | E59: Stock | F59: 610 | G59: 118.31 | H59: USD | I59: 72169.1 | J59: 10 | K59: 72179.1 | L59: 1220 | M59: Execution error: Misclick resulted in additional 610 shares purchased instead of sell. Corrective sell executed immediately after.
A60: 46111 | B60: Close | C60: TGT | D60: Target Corp | E60: Stock | F60: 1220 | G60: 118.14 | H60: USD | I60: -144130.8 | J60: 10 | K60: -144120.8 | L60: 0 | M60: Corrective full close of TGT. Liquidating retail exposure; broad market inflation fears render consumer discretionary vulnerable.
A61: 46111 | B61: Close | C61: PG | D61: Procter & Gamble Co. | E61: Stock | F61: 235 | G61: 144.83 | H61: USD | I61: -34035.05 | J61: 10 | K61: -34025.05 | L61: 0 | M61: Closing defensive position; in a severe downturn, defensives bleed too slowly to provide alpha needed in final 12 days.
A62: 46111 | B62: Close | C62: IONQ | D62: IonQ Inc | E62: Stock | F62: 800 | G62: 26.07 | H62: USD | I62: -20856 | J62: 10 | K62: -20846 | L62: 0 | M62: Emergency cut: speculative quantum position down 21%. Unprofitable tech must be liquidated in risk-off environment.
A63: 46111 | B63: Close | C63: NBIS | D63: Nebius Group N.V. – Class A | E63: Stock | F63: 135 | G63: 89.92 | H63: USD | I63: -12139.2 | J63: 10 | K63: -12129.2 | L63: 0 | M63: Cutting speculative AI satellite; down over 27%. High-beta tech is untenable during broader tech correction.
A64: 46111 | B64: Close | C64: JNJ | D64: Johnson & Johnson | E64: Stock | F64: 260 | G64: 241.88 | H64: USD | I64: -62888.8 | J64: 10 | K64: -62878.8 | L64: 0 | M64: Closing healthcare defensive to free capital. Dividend yield insufficient to offset rapid market drawdown in 12-day window.
A65: 46111 | B65: Open | C65: CENX | D65: Century Aluminum Co. | E65: Stock | F65: 1150 | G65: 53.49 | H65: USD | I65: 61513.5 | J65: 10 | K65: 61523.5 | L65: 1150 | M65: Momentum play: aluminum stocks surging on Middle East supply shock. Pure-play exposure to geopolitically-driven supply crunch.
...

Sheet Trading Log-Past
A1: Date (YYYY-MM-DD) | B1: Action (Open / Close / Adjust / No Action) | C1: Ticker | D1: Asset Name | E1: Type (Stock, ETF, Bond, FX, etc.) | F1: Quantity (positive number) | G1: Price per Unit | H1: Trade Currency | I1: Gross Trade Value (=Qty*Price) | J1: Fees / Commission | K1: Net Trade Value | L1: Position After Trade (units) | M1: Brief Reason (or reason for no change)
A2: 46065 | B2: Open | C2: SPY | D2: SPDR S&P 500 ETF Trust | E2: ETF | F2: 295 | G2: 684.89 | H2: USD | I2: =TradingLogTable[[#This Row],[Quantity (positive number)]]*TradingLogTable[[#This Row],[Price per Unit]] -> 202042.55 | J2: 10 | K2: =I2+J2 -> 202052.55 | L2: 295 | M2: Broad exposure to the U.S. market. Core long-term holding.
A3: 46065 | B3: Open | C3: LMT | D3: Lockhead Martin Corp | E3: Stock | F3: 100 | G3: 643.25 | H3: USD | I3: =TradingLogTable[[#This Row],[Quantity (positive number)]]*TradingLogTable[[#This Row],[Price per Unit]] -> 64325 | J3: 10 | K3: =I3+J3 -> 64335 | L3: 100 | M3: Defense company with stable government contracts.
A4: 46065 | B4: Open | C4: XLP | D4: Consumer Staples Select Sector SPDR | E4: ETF | F4: 875 | G4: 89.52 | H4: USD | I4: =TradingLogTable[[#This Row],[Quantity (positive number)]]*TradingLogTable[[#This Row],[Price per Unit]] -> 78330 | J4: 10 | K4: =I4+J4 -> 78340 | L4: 875 | M4: Consumer staples ETF. Defensive and stable.
A5: 46065 | B5: Open | C5: JNJ | D5: Johnson & Johnson | E5: Stock | F5: 260 | G5: 244.64 | H5: USD | I5: =TradingLogTable[[#This Row],[Quantity (positive number)]]*TradingLogTable[[#This Row],[Price per Unit]] -> 63606.4 | J5: 10 | K5: =I5+J5 -> 63616.4 | L5: 260 | M5: Healthcare stock. Reliable and defensive.
A6: 46065 | B6: Open | C6: PG | D6: Proctor & Gamble Co. | E6: Stock | F6: 235 | G6: 162.45 | H6: USD | I6: =TradingLogTable[[#This Row],[Quantity (positive number)]]*TradingLogTable[[#This Row],[Price per Unit]] -> 38175.75 | J6: 10 | K6: =I6+J6 -> 38185.75 | L6: 235 | M6: Strong global brands. Steady performance.
A7: 46065 | B7: Open | C7: WMT | D7: Walmart Inc. | E7: Stock | F7: 570 | G7: 132.95 | H7: USD | I7: =TradingLogTable[[#This Row],[Quantity (positive number)]]*TradingLogTable[[#This Row],[Price per Unit]] -> 75781.5 | J7: 10 | K7: =I7+J7 -> 75791.5 | L7: 570 | M7: Large retailer. Performs well even in slow economies.
A8: 46065 | B8: Open | C8: XLU | D8: Utilities Select Sector SPDR | E8: ETF | F8: 800 | G8: 45.45 | H8: USD | I8: =TradingLogTable[[#This Row],[Quantity (positive number)]]*TradingLogTable[[#This Row],[Price per Unit]] -> 36360 | J8: 10 | K8: =I8+J8 -> 36370 | L8: 800 | M8: Utilities ETF. Low risk and stable returns.
A9: 46070 | B9: Open | C9: TSM | D9: Taiwan Semiconductor Manufacturing - ADR | E9: Stock | F9: 230 | G9: 363.94 | H9: USD | I9: =TradingLogTable[[#This Row],[Quantity (positive number)]]*TradingLogTable[[#This Row],[Price per Unit]] -> 83706.2 | J9: 10 | K9: =I9+J9 -> 83716.2 | L9: 230 | M9: AI chip foundry, 30% revenue growth guidance 2026
A10: 46070 | B10: Open | C10: MU | D10: Micron Technology Inc. | E10: Stock | F10: 110 | G10: 408.82 | H10: USD | I10: =TradingLogTable[[#This Row],[Quantity (positive number)]]*TradingLogTable[[#This Row],[Price per Unit]] -> 44970.2 | J10: 10 | K10: =I10+J10 -> 44980.2 | L10: 110 | M10: HBM memory for AI data centers, fully booked 2026
A11: 46070 | B11: Open | C11: PLTR | D11: Palantir Technologies Inc | E11: Stock | F11: 388 | G11: 131.48 | H11: USD | I11: =TradingLogTable[[#This Row],[Quantity (positive number)]]*TradingLogTable[[#This Row],[Price per Unit]] -> 51014.24 | J11: 10 | K11: =I11+J11 -> 51024.24 | L11: 388 | M11: AI software platform, government defense contracts
A12: 46070 | B12: Open | C12: JPM | D12: JPMorgan Chase & Co. | E12: Stock | F12: 150 | G12: 306.82 | H12: USD | I12: =TradingLogTable[[#This Row],[Quantity (positive number)]]*TradingLogTable[[#This Row],[Price per Unit]] -> 46023 | J12: 10 | K12: =I12+J12 -> 46033 | L12: 150 | M12: Banking sector exposure, diversified financials
A13: 46070 | B13: Open | C13: AMZN | D13: Amazon.com Inc. | E13: Stock | F13: 250 | G13: 200.87 | H13: USD | I13: =TradingLogTable[[#This Row],[Quantity (positive number)]]*TradingLogTable[[#This Row],[Price per Unit]] -> 50217.5 | J13: 10 | K13: =I13+J13 -> 50227.5 | L13: 250 | M13: E-commerce leader plus AWS cloud infrastructure
... A32: 46083 | B32: No Action | C32: IONQ | D32: IonQ Inc | E32: Stock | F32: 800 | G32: 33.6 | H32: USD | I32: =TradingLogTable[[#This Row],[Quantity (positive number)]]*TradingLogTable[[#This Row],[Price per Unit]] -> 26880 | J32: 10 | K32: =I32+J32 -> 26890 | L32: 800 | M32: Down -8.39%. Speculative quantum computing position, sized at 2.7% of total portfolio. Long-term thesis unchanged; short-term volatility expected for early-stage tech. Stop-loss placed at $25. Hold.
A33: 46083 | B33: Open | C33: XLE | D33: SSgA Active Trust - The Energy Select Sector SPDR | E33: ETF | F33: 60 | G33: 57.95 | H33: USD | I33: =TradingLogTable[[#This Row],[Quantity (positive number)]]*TradingLogTable[[#This Row],[Price per Unit]] -> 3477 | J33: 10 | K33: =I33+J33 -> 3487 | L33: =TradingLogTable[[#This Row],[Quantity (positive number)]] -> 60 | M33: Energy sector ETF. Geopolitical risk premium from US-Iran standoff supports near-term oil price. Tactical position
A34: 46083 | B34: Open | C34: XOM | D34: Exxon Mobil Corp | E34: Stock | F34: 75 | G34: 159.75 | H34: USD | I34: =TradingLogTable[[#This Row],[Quantity (positive number)]]*TradingLogTable[[#This Row],[Price per Unit]] -> 11981.25 | J34: 10 | K34: =I34+J34 -> 11991.25 | L34: =TradingLogTable[[#This Row],[Quantity (positive number)]] -> 75 | M34: Integrated oil major. Geopolitical hedging. . Benefits from elevated crude oil and strong margins.
A36: 46084 | B36: No Action | C36: SPY | D36: SPDR S&P 500 ETF Trust | E36: ETF | F36: 295 | G36: 684.89 | H36: USD | I36: =TradingLogTable[[#This Row],[Quantity (positive number)]]*TradingLogTable[[#This Row],[Price per Unit]] -> 202042.55 | J36: 10 | K36: =I36+J36 -> 202052.55 | L36: 295 | M36: Core benchmark exposure. Portfolio outperforming S&P this period. Thesis unchanged; no stop-loss on index. Hold.
A37: 46084 | B37: No Action | C37: XLP | D37: Consumer Staples Select Sector SPDR | E37: ETF | F37: 875 | G37: 89.52 | H37: USD | I37: 78330 | J37: 10 | K37: 78340 | L37: 875 | M37: Consumer staples ETF. Minor unrealized loss within normal range. Defensive allocation working as intended. Hold.
A38: 46084 | B38: No Action | C38: JNJ | D38: Johnson & Johnson | E38: Stock | F38: 260 | G38: 244.64 | H38: USD | I38: 63606.4 | J38: 10 | K38: 63616.4 | L38: 260 | M38: Healthcare defensive. Stable earnings and dividend profile unchanged. Hold.
A39: 46084 | B39: No Action | C39: PG | D39: Procter & Gamble Co. | E39: Stock | F39: 235 | G39: 162.45 | H39: USD | I39: 38175.75 | J39: 10 | K39: 38185.75 | L39: 235 | M39: FMCG defensive. Strong global brands and resilient demand. Hold.
A40: 46084 | B40: No Action | C40: WMT | D40: Walmart Inc. | E40: Stock | F40: 570 | G40: 132.95 | H40: USD | I40: 75781.5 | J40: 10 | K40: 75791.5 | L40: 570 | M40: Down about 5%. Retail under pressure, but defensive thesis intact. Stop-loss placed at $118. Monitor.
A41: 46084 | B41: No Action | C41: XLU | D41: Utilities Select Sector SPDR | E41: ETF | F41: 800 | G41: 45.45 | H41: USD | I41: 36360 | J41: 10 | K41: 36370 | L41: 800 | M41: Utilities ETF. Low‑beta defensive working during volatility. Hold.
A42: 46084 | B42: No Action | C42: TSM | D42: Taiwan Semiconductor Manufacturing – ADR | E42: Stock | F42: 230 | G42: 363.94 | H42: USD | I42: 83706.2 | J42: 10 | K42: 83716.2 | L42: 230 | M42: AI foundry thesis intact and strengthening. Guidance unchanged. Hold.
A43: 46084 | B43: Adjust | C43: MU | D43: Micron Technology Inc. | E43: Stock | F43: 95 | G43: 381.14 | H43: USD | I43: -36208.3 | J43: 10 | K43: -36198.3 | L43: 15 | M43: Trailing stop-loss on MU triggered; trimmed 95 shares after strong run, kept 15‑share residual for AI memory thesis.
A44: 46084 | B44: No Action | C44: PLTR | D44: Palantir Technologies Inc. | E44: Stock | F44: 388 | G44: 131.48 | H44: USD | I44: 51014.24 | J44: 10 | K44: 51024.24 | L44: 388 | M44: AI defense software thesis intact. Volatility within acceptable range. Hold. | O44: =COUNT(G36:G62) -> 27
A45: 46084 | B45: No Action | C45: JPM | D45: JPMorgan Chase & Co. | E45: Stock | F45: 150 | G45: 306.82 | H45: USD | I45: 46023 | J45: 10 | K45: 46033 | L45: 150 | M45: Slight drawdown on rate repricing. Banking fundamentals unchanged. Hold (before later exit).
A46: 46084 | B46: No Action | C46: AMZN | D46: Amazon.com Inc. | E46: Stock | F46: 250 | G46: 200.87 | H46: USD | I46: 50217.5 | J46: 10 | K46: 50227.5 | L46: 250 | M46: AWS cloud and e‑commerce thesis intact; AI workloads support demand. Hold.
A47: 46084 | B47: No Action | C47: GOOGL | D47: Alphabet Inc – Class A | E47: Stock | F47: 130 | G47: 302.22 | H47: USD | I47: 39288.6 | J47: 10 | K47: 39298.6 | L47: 130 | M47: Big tech AI infrastructure thesis intact. Gemini and search dominance support. Trailing stop at 7%. Hold.
A48: 46084 | B48: No Action | C48: GE | D48: GE Aerospace | E48: Stock | F48: 140 | G48: 329.44 | H48: USD | I48: 46121.6 | J48: 10 | K48: 46131.6 | L48: 140 | M48: Industrial/aerospace thesis intact. Up ~3%. Trailing stop at 5% in place prior to trigger. Hold at check‑in.
A49: 46084 | B49: No Action | C49: IONQ | D49: IonQ Inc | E49: Stock | F49: 800 | G49: 33.6 | H49: USD | I49: 26880 | J49: 10 | K49: 26890 | L49: 800 | M49: Speculative quantum computing, sized ~2.7% of portfolio. Long‑term thesis; short‑term volatility expected. Hold.
A50: 46084 | B50: No Action | C50: XLE | D50: Energy Select Sector SPDR | E50: ETF | F50: 60 | G50: 57.95 | H50: USD | I50: 3477 | J50: 10 | K50: 3487 | L50: 60 | M50: Energy ETF. Geopolitical risk premium from US–Iran tensions supports near‑term oil prices. Tactical position.
A51: 46084 | B51: No Action | C51: XOM | D51: Exxon Mobil Corp | E51: Stock | F51: 75 | G51: 159.75 | H51: USD | I51: 11981.25 | J51: 10 | K51: 11991.25 | L51: 75 | M51: Integrated oil major. Geopolitical hedge benefiting from elevated crude and strong margins. Hold.
A52: 46084 | B52: Close | C52: GE | D52: GE Aerospace | E52: Stock | F52: 140 | G52: 329.81 | H52: USD | I52: -46173.4 | J52: 10 | K52: -46163.4 | L52: 0 | M52: Trailing stop-loss hit on GE later that day; full position closed to protect gains and free capital.
A53: 46085 | B53: Close | C53: LMT | D53: Lockheed Martin Corp. | E53: Stock | F53: 100 | G53: 654.18 | H53: USD | I53: -65418 | J53: 10 | K53: -65408 | L53: 0 | M53: Trailing stop on LMT triggered; locked in profit before reassessing entry.
A54: 46090 | B54: No Action | C54: GOOGL | D54: Alphabet Inc – Class A | E54: Stock | F54: 130 | G54: 0.21 | H54: USD | I54: 27.3 | J54: 0 | K54: 27.3 | L54: 130 | M54: Dividend payment received on GOOGL; no change to position size or thesis.
A55: 46093 | B55: Close | C55: WMT | D55: Walmart Inc. | E55: Stock | F55: 570 | G55: 124.61 | H55: USD | I55: -71027.7 | J55: 10 | K55: -71017.7 | L55: 0 | M55: Closed WMT after sustained underperformance; capital reallocated to higher‑conviction retail (TGT).
A56: 46093 | B56: Close | C56: JPM | D56: JPMorgan Chase & Co. | E56: Stock | F56: 150 | G56: 281.04 | H56: USD | I56: -42156 | J56: 10 | K56: -42146 | L56: 0 | M56: Exited JPM as financials lag and rate‑cut expectations shift; redeploying capital into other sectors.
... A65: 46097 | B65: Open | C65: SIEGY | D65: Siemens AG – ADR | E65: Stock | F65: 150 | G65: 126.695 | H65: USD | I65: 19004.25 | J65: 10 | K65: 19014.25 | L65: 150 | M65: European industrial core with strong electrification/automation order book, adding non‑US energy‑transition exposure beyond XOM/XLE.
I66: =_xlfn.FORMULATEXT(I18) -> =[@[Quantity (positive number)]]*[@[Price per Unit]]
K68: =SUM(K36:K65) -> 859701.36

Sheet Live Data
C1: Name | D1: Exchange Abbreviation | E1: Instrument Type | F1: Last trade time | G1: Volume | H1: Open | I1: Beta | J1: Price | K1: Change | L1: Change (%) | M1: High | N1: Low | O1: 52 Week High | P1: 52 week low | Q1: Previous Close | R1: Market Cap
B2: PSQ | C2: #VALUE! | D2: {=_FV(C2,"Exchange abbreviation",TRUE)} -> ARCX | E2: {=_FV(C2,"Instrument type",TRUE)} -> ETF | F2: {=_FV(C2,"Last trade time",TRUE)} -> 46111.88 | G2: {=_FV(C2,"Volume")} -> 10764765 | H2: {=_FV(C2,"Open")} -> 32.76 | I2: {=_FV(C2,"Beta")} -> -0.9586 | J2: {=_FV(C2,"Price")} -> 33.3 | K2: {=_FV(C2,"Change")} -> 0.26 | L2: {=_FV(C2,"Change (%)",TRUE)} -> 0.007869 | M2: {=_FV(C2,"High")} -> 33.4699 | N2: {=_FV(C2,"Low")} -> 32.735 | O2: {=_FV(C2,"52 week high",TRUE)} -> 46.98 | P2: {=_FV(C2,"52 week low",TRUE)} -> 29.24 | Q2: {=_FV(C2,"Previous close",TRUE)} -> 33.04 | R2: {=_FV(C2,"Market cap",TRUE)} -> 6.3988653e+08
B3: XLE | C3: #VALUE! | D3: {=_FV(C3,"Exchange abbreviation",TRUE)} -> ARCX | E3: {=_FV(C3,"Instrument type",TRUE)} -> ETF | F3: {=_FV(C3,"Last trade time",TRUE)} -> 46111.882 | G3: {=_FV(C3,"Volume")} -> 49629980 | H3: {=_FV(C3,"Open")} -> 63.13 | I3: {=_FV(C3,"Beta")} -> 1.1237 | J3: {=_FV(C3,"Price")} -> 61.95 | K3: {=_FV(C3,"Change")} -> -0.61 | L3: {=_FV(C3,"Change (%)",TRUE)} -> -0.009751 | M3: {=_FV(C3,"High")} -> 63.46 | N3: {=_FV(C3,"Low")} -> 61.78 | O3: {=_FV(C3,"52 week high",TRUE)} -> 63.46 | P3: {=_FV(C3,"52 week low",TRUE)} -> 37.245 | Q3: {=_FV(C3,"Previous close",TRUE)} -> 62.56 | R3: {=_FV(C3,"Market cap",TRUE)} -> 3.7876245e+10
B4: XLU | C4: #VALUE! | D4: {=_FV(C4,"Exchange abbreviation",TRUE)} -> ARCX | E4: {=_FV(C4,"Instrument type",TRUE)} -> ETF | F4: {=_FV(C4,"Last trade time",TRUE)} -> 46111.882 | G4: {=_FV(C4,"Volume")} -> 28257443 | H4: {=_FV(C4,"Open")} -> 46.17 | I4: {=_FV(C4,"Beta")} -> 0.9975 | J4: {=_FV(C4,"Price")} -> 45.93 | K4: {=_FV(C4,"Change")} -> 0.34 | L4: {=_FV(C4,"Change (%)",TRUE)} -> 0.007458 | M4: {=_FV(C4,"High")} -> 46.335 | N4: {=_FV(C4,"Low")} -> 45.755 | O4: {=_FV(C4,"52 week high",TRUE)} -> 47.8 | P4: {=_FV(C4,"52 week low",TRUE)} -> 35.51 | Q4: {=_FV(C4,"Previous close",TRUE)} -> 45.59 | R4: {=_FV(C4,"Market cap",TRUE)} -> 2.4356755e+10
B5: SH | C5: #VALUE! | D5: {=_FV(C5,"Exchange abbreviation",TRUE)} -> ARCX | E5: {=_FV(C5,"Instrument type",TRUE)} -> ETF | F5: {=_FV(C5,"Last trade time",TRUE)} -> 46111.881 | G5: {=_FV(C5,"Volume")} -> 13299114 | H5: {=_FV(C5,"Open")} -> 38.545 | I5: {=_FV(C5,"Beta")} -> -0.9783 | J5: {=_FV(C5,"Price")} -> 39.03 | K5: {=_FV(C5,"Change")} -> 0.14 | L5: {=_FV(C5,"Change (%)",TRUE)} -> 0.0036 | M5: {=_FV(C5,"High")} -> 39.2 | N5: {=_FV(C5,"Low")} -> 38.52 | O5: {=_FV(C5,"52 week high",TRUE)} -> 51.3706 | P5: {=_FV(C5,"52 week low",TRUE)} -> 35.34 | Q5: {=_FV(C5,"Previous close",TRUE)} -> 38.89 | R5: {=_FV(C5,"Market cap",TRUE)} -> 1.0435744e+09
B6: XLP | C6: #VALUE! | D6: {=_FV(C6,"Exchange abbreviation",TRUE)} -> ARCX | E6: {=_FV(C6,"Instrument type",TRUE)} -> ETF | F6: {=_FV(C6,"Last trade time",TRUE)} -> 46111.882 | G6: {=_FV(C6,"Volume")} -> 15853421 | H6: {=_FV(C6,"Open")} -> 81.905 | I6: {=_FV(C6,"Beta")} -> 0.9722 | J6: {=_FV(C6,"Price")} -> 81.8844 | K6: {=_FV(C6,"Change")} -> 0.1044 | L6: {=_FV(C6,"Change (%)",TRUE)} -> 0.001277 | M6: {=_FV(C6,"High")} -> 82.605 | N6: {=_FV(C6,"Low")} -> 81.63 | O6: {=_FV(C6,"52 week high",TRUE)} -> 90.14 | P6: {=_FV(C6,"52 week low",TRUE)} -> 75.16 | Q6: {=_FV(C6,"Previous close",TRUE)} -> 81.78 | R6: {=_FV(C6,"Market cap",TRUE)} -> 1.7557142e+10
B7: IBB | C7: #VALUE! | D7: {=_FV(C7,"Exchange abbreviation",TRUE)} -> XNAS | E7: {=_FV(C7,"Instrument type",TRUE)} -> ETF | F7: {=_FV(C7,"Last trade time",TRUE)} -> 46111.875 | G7: {=_FV(C7,"Volume")} -> 1495238 | H7: {=_FV(C7,"Open")} -> 161.79 | I7: {=_FV(C7,"Beta")} -> 0.9874 | J7: {=_FV(C7,"Price")} -> 161.86 | K7: {=_FV(C7,"Change")} -> 1.45 | L7: {=_FV(C7,"Change (%)",TRUE)} -> 0.009039 | M7: {=_FV(C7,"High")} -> 162.95 | N7: {=_FV(C7,"Low")} -> 160.56 | O7: {=_FV(C7,"52 week high",TRUE)} -> 179.64 | P7: {=_FV(C7,"52 week low",TRUE)} -> 107.43 | Q7: {=_FV(C7,"Previous close",TRUE)} -> 160.41 | R7: {=_FV(C7,"Market cap",TRUE)} -> 8.7840367e+09
B8: GLD | C8: #VALUE! | D8: {=_FV(C8,"Exchange abbreviation",TRUE)} -> ARCX | E8: {=_FV(C8,"Instrument type",TRUE)} -> ETF | F8: {=_FV(C8,"Last trade time",TRUE)} -> 46111.882 | G8: {=_FV(C8,"Volume")} -> 13116517 | H8: {=_FV(C8,"Open")} -> 419.54 | I8: {=_FV(C8,"Beta")} -> 0.8008 | J8: {=_FV(C8,"Price")} -> 414.62 | K8: {=_FV(C8,"Change")} -> -0.08 | L8: {=_FV(C8,"Change (%)",TRUE)} -> -0.0001929 | M8: {=_FV(C8,"High")} -> 420.1 | N8: {=_FV(C8,"Low")} -> 412.66 | O8: {=_FV(C8,"52 week high",TRUE)} -> 509.7 | P8: {=_FV(C8,"52 week low",TRUE)} -> 272.58 | Q8: {=_FV(C8,"Previous close",TRUE)} -> 414.7 | R8: {=_FV(C8,"Market cap",TRUE)} -> 1.8486229e+11
B9: LMT | C9: #VALUE! | D9: {=_FV(C9,"Exchange abbreviation",TRUE)} -> XNYS | E9: {=_FV(C9,"Instrument type",TRUE)} -> Stock | F9: {=_FV(C9,"Last trade time",TRUE)} -> 46111.88 | G9: {=_FV(C9,"Volume")} -> 1847963 | H9: {=_FV(C9,"Open")} -> 621.03 | I9: {=_FV(C9,"Beta")} -> 0.2394 | J9: {=_FV(C9,"Price")} -> 598.56 | K9: {=_FV(C9,"Change")} -> -17.28 | L9: {=_FV(C9,"Change (%)",TRUE)} -> -0.028059 | M9: {=_FV(C9,"High")} -> 623.32 | N9: {=_FV(C9,"Low")} -> 593.88 | O9: {=_FV(C9,"52 week high",TRUE)} -> 692 | P9: {=_FV(C9,"52 week low",TRUE)} -> 410.11 | Q9: {=_FV(C9,"Previous close",TRUE)} -> 615.84 | R9: {=_FV(C9,"Market cap",TRUE)} -> 137945394576
B10: MU | C10: #VALUE! | D10: {=_FV(C10,"Exchange abbreviation",TRUE)} -> XNAS | E10: {=_FV(C10,"Instrument type",TRUE)} -> Stock | F10: {=_FV(C10,"Last trade time",TRUE)} -> 46111.882 | G10: {=_FV(C10,"Volume")} -> 72834342 | H10: {=_FV(C10,"Open")} -> 362.66 | I10: {=_FV(C10,"Beta")} -> 1.5698 | J10: {=_FV(C10,"Price")} -> 321.8 | K10: {=_FV(C10,"Change")} -> -35.27 | L10: {=_FV(C10,"Change (%)",TRUE)} -> -0.098776 | M10: {=_FV(C10,"High")} -> 362.81 | N10: {=_FV(C10,"Low")} -> 318.4 | O10: {=_FV(C10,"52 week high",TRUE)} -> 471.34 | P10: {=_FV(C10,"52 week low",TRUE)} -> 61.54 | Q10: {=_FV(C10,"Previous close",TRUE)} -> 357.07 | R10: {=_FV(C10,"Market cap",TRUE)} -> 362904801200
B11: ITA | C11: #VALUE! | D11: {=_FV(C11,"Exchange abbreviation",TRUE)} -> BATS | E11: {=_FV(C11,"Instrument type",TRUE)} -> ETF | F11: {=_FV(C11,"Last trade time",TRUE)} -> 46111.879 | G11: {=_FV(C11,"Volume")} -> 1473711 | H11: {=_FV(C11,"Open")} -> 217.34 | I11: {=_FV(C11,"Beta")} -> 0.9453 | J11: {=_FV(C11,"Price")} -> 210.67 | K11: {=_FV(C11,"Change")} -> -5.37 | L11: {=_FV(C11,"Change (%)",TRUE)} -> -0.024857 | M11: {=_FV(C11,"High")} -> 218.5 | N11: {=_FV(C11,"Low")} -> 209.31 | O11: {=_FV(C11,"52 week high",TRUE)} -> 250.65 | P11: {=_FV(C11,"52 week low",TRUE)} -> 129.14 | Q11: {=_FV(C11,"Previous close",TRUE)} -> 216.04 | R11: {=_FV(C11,"Market cap",TRUE)} -> 1.6010935e+10
B12: XOM | C12: #VALUE! | D12: {=_FV(C12,"Exchange abbreviation",TRUE)} -> XNYS | E12: {=_FV(C12,"Instrument type",TRUE)} -> Stock | F12: {=_FV(C12,"Last trade time",TRUE)} -> 46111.882 | G12: {=_FV(C12,"Volume")} -> 29663929 | H12: {=_FV(C12,"Open")} -> 172.505 | I12: {=_FV(C12,"Beta")} -> 0.2561 | J12: {=_FV(C12,"Price")} -> 171.5 | K12: {=_FV(C12,"Change")} -> 0.51 | L12: {=_FV(C12,"Change (%)",TRUE)} -> 0.002983 | M12: {=_FV(C12,"High")} -> 176.41 | N12: {=_FV(C12,"Low")} -> 171.05 | O12: {=_FV(C12,"52 week high",TRUE)} -> 176.41 | P12: {=_FV(C12,"52 week low",TRUE)} -> 97.8 | Q12: {=_FV(C12,"Previous close",TRUE)} -> 170.99 | R12: {=_FV(C12,"Market cap",TRUE)} -> 714600026000
B13: AA | C13: #VALUE! | D13: {=_FV(C13,"Exchange abbreviation",TRUE)} -> XNYS | E13: {=_FV(C13,"Instrument type",TRUE)} -> Stock | F13: {=_FV(C13,"Last trade time",TRUE)} -> 46111.878 | G13: {=_FV(C13,"Volume")} -> 12888491 | H13: {=_FV(C13,"Open")} -> 64 | I13: {=_FV(C13,"Beta")} -> 1.7302 | J13: {=_FV(C13,"Price")} -> 63.21 | K13: {=_FV(C13,"Change")} -> 4.8 | L13: {=_FV(C13,"Change (%)",TRUE)} -> 0.082178 | M13: {=_FV(C13,"High")} -> 66 | N13: {=_FV(C13,"Low")} -> 62.13 | O13: {=_FV(C13,"52 week high",TRUE)} -> 68.4 | P13: {=_FV(C13,"52 week low",TRUE)} -> 21.53 | Q13: {=_FV(C13,"Previous close",TRUE)} -> 58.41 | R13: {=_FV(C13,"Market cap",TRUE)} -> 16678754946
... B20: PLTR | C20: #VALUE! | D20: {=_FV(C20,"Exchange abbreviation",TRUE)} -> XNAS | E20: {=_FV(C20,"Instrument type",TRUE)} -> Stock | F20: {=_FV(C20,"Last trade time",TRUE)} -> 46111.882 | G20: {=_FV(C20,"Volume")} -> 40823306 | H20: {=_FV(C20,"Open")} -> 143.27 | I20: {=_FV(C20,"Beta")} -> 1.64 | J20: {=_FV(C20,"Price")} -> 137.55 | K20: {=_FV(C20,"Change")} -> -5.51 | L20: {=_FV(C20,"Change (%)",TRUE)} -> -0.038515 | M20: {=_FV(C20,"High")} -> 144.12 | N20: {=_FV(C20,"Low")} -> 136.3 | O20: {=_FV(C20,"52 week high",TRUE)} -> 207.52 | P20: {=_FV(C20,"52 week low",TRUE)} -> 66.12 | Q20: {=_FV(C20,"Previous close",TRUE)} -> 143.06 | R20: {=_FV(C20,"Market cap",TRUE)} -> 328836796050

Sheet Periodic Reflection
A1: Reporting Period Start (YYYY-MM-DD) | B1: Reporting Period End (YYYY-MM-DD) | C1: Strategy Summary (4–8 lines) | D1: Top 3 Decisions & Why (bullets) | E1: What You Learned / Next Steps
A2: 45692 | B2: 46070 | C2: Momentum with risk caps per position (max 3% of portfolio). Focus on large-cap tech breakouts and macro-sensitive names ahead of CPI. | D2: Made SPY the foundation to reduce single-stock risk Added LMT for stable defense-sector exposure Overweighted defensive sectors to protect against downturns | E2: Maintain defensive positioning while monitoring sector concentration risk; avoid over-allocating to low-volatility names. Next: consider adding selective growth or international exposure and rebalance if defensive weight becomes excessive.
A3: =B2+1 -> 46071 | B3: 46083 | C3: The portfolio's moderate-risk, fundamentals-first mandate was maintained throughout, with no position exceeding 9% of total capital and no sector breaching the 25% concentration limit. | D3: Short-term geopolitical spike opened on XLE and XOM Held all positions through market decline Placed protective stops on WMT, IONQ (stop-loss) and LMT, GE, MU, GOOGL (trailing stops) | E3: Learned: Defensive sector rotation (staples, utilities) behaves as expected during broad market selloffs, validating the barbell construction Position sizing matters more than individual stock selection — WMT and IONQ caused noise but couldn't meaningfully damage the portfolio because neither exceeded 8% of capital Next Steps: Monitor WMT and IONQ weekly; if either breaches its stop-loss, log the close and reallocate proceeds to a higher-conviction position Log 3 check-in: reassess JPM given Fed rate trajectory and whether financials sector thesis remains intact Consider initiating a small position to bring the portfolio closer to the 60/40 charter target if equity volatility increases
A4: =B3+1 -> 46084 | B4: 46097 | C4: The first two weeks of March marked a deliberate gear shift. Capital preservation gave way to high-conviction growth plays after trailing stops did their job on GE, MU, and LMT during that early-month turbulence. The freed-up cash went straight into the "AI Power & Infra" thesis, concentrated in NVDA, ORCL, and NBIS. Defense didn't get abandoned, though. LMT came back into the portfolio alongside ITA to keep the geopolitical hedge intact. On the retail side, WMT wasn't pulling its weight relative to the sector, so it got swapped for TGT after solid earnings data confirmed the thesis. | D4: The WMT exit was overdue. The position was dragging behind the broader consumer discretionary space, and TGT (610 units) offered a cleaner entry with better near-term momentum. Simple upgrade in quality, nothing exotic. The real alpha play was channeling stopped-out capital into NVDA and ORCL right before the GTC Conference window. Timing mattered here. The AI infrastructure narrative had a concrete catalyst on the calendar, and sitting in cash while that played out would have been a waste of the rotation opportunity. LMT's re-entry deserves its own note. The trailing stop that triggered wasn't a conviction call; it was mechanical. The original macro thesis on rising global military budgets hadn't changed one bit. So the correction was manual: re-enter LMT, add ITA for broader defense diversification, and restore the portfolio's intended structure. | E4: Learned Trailing stops worked exactly as designed on GE and MU. They locked in gains during volatility. But the LMT situation exposed a gap: when a stop fires on a position you still believe in fundamentally, you need a re-entry protocol, not just a "wait and see" reflex. That's a process improvement I'm codifying going forward. The Gemini-driven tech selloff also reinforced something I already suspected; high-beta names need wider stop buffers. Tight stops on volatile positions just generate unnecessary churn. Next Steps NVDA and ORCL are the immediate watchlist. Post-conference price action will dictate whether stops get tightened or left loose. SIEGY is on the radar as a potential European industrial hedge, worth a deeper look in the next cycle. And IBB's recent leadership in biotech raises a real question: does it merit scaling from a satellite position into a core allocation? That answer depends on whether the momentum sustains through April.
A5: EMERGENCY TRIAGE THESIS CHANGE
A6: 46098 | B6: 46111 | C6: With 12 trading days remaining and the portfolio sitting last in class rankings, the team invoked the emergency clause in Section 5 of the Team Charter to override the standard 60% equity / moderate-risk mandate. The market entered a confirmed correction: the S&P 500 is down 8.82% YTD, the Nasdaq is in correction territory, and geopolitical escalation (US-Iran, war deadline fears) is driving a broad risk-off environment. The team executed a full liquidation of underperforming and thesis-broken longs (SPY, TSM, TGT, PG, IONQ, NBIS, JNJ) and redeployed ~$495,000 into an offensive turnaround allocation: PSQ and SH as inverse index hedges to profit directly from the ongoing correction, GLD as a safe-haven capital flight trade, and AA and CENX as a geopolitical momentum trade following Middle East supply disruptions to aluminum markets. Two execution errors (misclicks on TSM and TGT) were identified and corrected immediately within the same session and documented transparently in the log. | D6: 1. Emergency charter override and full liquidation of longs: The thesis for holding SPY, TSM, TGT, PG, IONQ, NBIS and JNJ broke under a confirmed market correction. Holding them was optimising for "hope the market recovers" rather than trading the actual environment. Liquidating freed $495K in capital to deploy offensively. 2. PSQ + SH inverse ETF allocation ($247K combined): The Nasdaq is in correction and the S&P is down ~9%. Buying inverse ETFs converts further market decline into direct positive portfolio returns, he only rational strategy when the trend is unambiguously down with 12 days left. 3. AA + CENX aluminum trade ($123K combined): A same-day geopolitical news catalyst (Middle East supply disruption) drove aluminum stocks up ~7% in a single session. This is a momentum trade with a clear, short-term, real-world catalyst, the type of trade uniquely suited to a 12-day closing window. | E6: The most important lesson from this simulation is that strategy must be adaptive, not static. Our original charter was built for a stable market; it was the wrong tool for a correction. Waiting too long to invoke the emergency override cost us several weeks of slow bleed. Next steps: monitor PSQ and SH daily, if the market shows a confirmed reversal signal (Fed pivot language, peace deal, strong jobs data), exit inverse positions immediately and rotate back into quality longs. Monitor AA and CENX for 3–5 day momentum window and set internal stops at. Final portfolio review scheduled for last trading log.
KI418: 1st log | KJ418: AssetClass | KK418: Value
KJ419: Cash | KK419: 44.17
KJ420: Long Equities | KK420: 55.83

Sheet Cover (2)
A1: #VALUE!
B5: Trading Log | K5: 1
J6: -
G11: Team 5 Lon 2
B12: The Investment Challenge - CHL-0200 | H12: Abdul Rafay Malik
B13: Prof. Daniela Neiderer | H13: Aliah Muhammad Asharaf
H14: Azriel Fernandes
B15: Date: | C15: 46070 | H15: Devarya Shah
H16: Kartavya Jharwal
H17: Nandini Prakash Rangani
H18: Pedro Junqueira
H19: Sayhan Mushrif

Sheet VALIDATION_LISTS
A1: Open | B1: Stock | C1: USD
A2: Close | B2: ETF | C2: GBP
A3: Adjust | B3: Bond | C3: EUR
A4: No Action | B4: Mutual Fund | C4: JPY
B5: FX | C5: CHF
B6: Crypto | C6: CAD
B7: Commodity | C7: AUD
B8: Index Future | C8: CNY
B9: Option
B10: Other
